2016-09-10 10:17:44,277 CRITICAL sys_exc_hook sys exception traceback
Traceback (most recent call last):
  File "run.py", line 129, in <module>
    server.serve_forever()
  File "/Users/fff/.pyenv/versions/venv2712/lib/python2.7/site-packages/gevent/baseserver.py", line 347, in serve_forever
    self.start()
  File "/Users/fff/.pyenv/versions/venv2712/lib/python2.7/site-packages/gevent/baseserver.py", line 291, in start
    self.init_socket()
  File "/Users/fff/.pyenv/versions/venv2712/lib/python2.7/site-packages/gevent/pywsgi.py", line 1222, in init_socket
    StreamServer.init_socket(self)
  File "/Users/fff/.pyenv/versions/venv2712/lib/python2.7/site-packages/gevent/server.py", line 80, in init_socket
    self.socket = self.get_listener(self.address, self.backlog, self.family)
  File "/Users/fff/.pyenv/versions/venv2712/lib/python2.7/site-packages/gevent/server.py", line 91, in get_listener
    return _tcp_listener(address, backlog=backlog, reuse_addr=self.reuse_addr, family=family)
  File "/Users/fff/.pyenv/versions/venv2712/lib/python2.7/site-packages/gevent/server.py", line 177, in _tcp_listener
    sock.bind(address)
  File "<string>", line 1, in bind
error: [Errno 48] Address already in use: ('127.0.0.1', 46123)
